Workbook

Sheet 2023
A1: =TODAY() -> 46121 | C1: T3 | H1: T4 | AL1: T5 | BQ1: T6 | CU1: T7 | DZ1: T8 | FE1: T9 | GI1: T10 | HN1: T11 | IR1: T12 | JW1: T1/2024
C2: 45012 | D2: 45013 | E2: 45014 | F2: 45015 | G2: 45016 | H2: 45017 | I2: 45018 | J2: 45019 | K2: 45020 | L2: 45021 | M2: 45022 | N2: 45023 | O2: 45024 | P2: 45025 | Q2: 45026 | R2: 45027 | S2: 45028 | T2: 45029 | U2: 45030 | V2: 45031 | W2: 45032 | X2: 45033 | Y2: 45034 | Z2: 45035 | AA2: 45036 | AB2: 45037 | AC2: 45038 | AD2: 45039 | AE2: 45040 | AF2: 45041 | AG2: 45042 | AH2: 45043 | AI2: 45044 | AJ2: 45045 | AK2: 45046 | AL2: 45047 | AM2: 45048 | AN2: 45049 | AO2: 45050 | AP2: 45051 | AQ2: 45052 | AR2: 45053 | AS2: 45054 | AT2: 45055 | AU2: 45056 | AV2: 45057 | AW2: 45058 | AX2: 45059 | AY2: 45060 | AZ2: 45061 | BA2: 45062 | BB2: 45063 | BC2: 45064 | BD2: 45065 | BE2: 45066 | BF2: 45067 | BG2: 45068 | BH2: 45069 | BI2: 45070 | BJ2: 45071 | BK2: 45072 | BL2: 45073 | BM2: 45074 | BN2: 45075 | BO2: 45076 | BP2: 45077 | BQ2: 45078 | BR2: 45079 | BS2: 45080 | BT2: 45081 | BU2: 45082 | BV2: 45083 | BW2: 45084 | BX2: 45085 | BY2: 45086 | BZ2: 45087 | CA2: 45088 | CB2: 45089 | CC2: 45090 | CD2: 45091 | CE2: 45092 | CF2: 45093 | CG2: 45094 | CH2: 45095 | CI2: 45096 | CJ2: 45097 | CK2: 45098 | CL2: 45099 | CM2: 45100 | CN2: 45101 | CO2: 45102 | CP2: 45103 | CQ2: 45104 | CR2: 45105 | CS2: 45106 | CT2: 45107 | CU2: 45108 | CV2: 45109 | CW2: 45110 | CX2: 45111 | CY2: 45112 | CZ2: 45113 | DA2: 45114 | DB2: 45115 | DC2: 45116 | DD2: 45117 | DE2: 45118 | DF2: 45119 | DG2: 45120 | DH2: 45121 | DI2: 45122 | DJ2: 45123 | DK2: 45124 | DL2: 45125 | DM2: 45126 | DN2: 45127 | DO2: 45128 | DP2: 45129 | DQ2: 45130 | DR2: 45131 | DS2: 45132 | DT2: 45133 | DU2: 45134 | DV2: 45135 | DW2: 45136 | DX2: 45137 | DY2: 45138 | DZ2: 45139 | EA2: 45140 | EB2: 45141 | EC2: 45142 | ED2: 45143 | EE2: 45144 | EF2: 45145 | EG2: 45146 | EH2: 45147 | EI2: 45148 | EJ2: 45149 | EK2: 45150 | EL2: 45151 | EM2: 45152 | EN2: 45153 | EO2: 45154 | EP2: 45155 | EQ2: 45156 | ER2: 45157 | ES2: 45158 | ET2: 45159 | EU2: 45160 | EV2: 45161 | EW2: 45162 | EX2: 45163 | EY2: 45164 | EZ2: 45165 | FA2: 45166 | FB2: 45167 | FC2: 45168 | FD2: 45169 | FE2: 45170 | FF2: 45171 | FG2: 45172 | FH2: 45173 | FI2: 45174 | FJ2: 45175 | FK2: 45176 | FL2: 45177 | FM2: 45178 | FN2: 45179 | FO2: 45180 | FP2: 45181 | FQ2: 45182 | FR2: 45183 | FS2: 45184 | FT2: 45185 | FU2: 45186 | FV2: 45187 | FW2: 45188 | FX2: 45189 | FY2: 45190 | FZ2: 45191 | GA2: 45192 | GB2: 45193 | GC2: 45194 | GD2: 45195 | GE2: 45196 | GF2: 45197 | GG2: 45198 | GH2: 45199 | GI2: 45200 | GJ2: 45201 | GK2: 45202 | GL2: 45203 | GM2: 45204 | GN2: 45205 | GO2: 45206 | GP2: 45207 | GQ2: 45208 | GR2: 45209 | GS2: 45210 | GT2: 45211 | GU2: 45212 | GV2: 45213 | GW2: 45214 | GX2: 45215 | GY2: 45216 | GZ2: 45217 | HA2: 45218 | HB2: 45219 | HC2: 45220 | HD2: 45221 | HE2: 45222 | HF2: 45223 | HG2: 45224 | HH2: 45225 | HI2: 45226 | HJ2: 45227 | HK2: 45228 | HL2: 45229 | HM2: 45230 | HN2: 45231 | HO2: 45232 | HP2: 45233 | HQ2: 45234 | HR2: 45235 | HS2: 45236 | HT2: 45237 | HU2: 45238 | HV2: 45239 | HW2: 45240 | HX2: 45241 | HY2: 45242 | HZ2: 45243 | IA2: 45244 | IB2: 45245 | IC2: 45246 | ID2: 45247 | IE2: 45248 | IF2: 45249 | IG2: 45250 | IH2: 45251 | II2: 45252 | IJ2: 45253 | IK2: 45254 | IL2: 45255 | IM2: 45256 | IN2: 45257 | IO2: 45258 | IP2: 45259 | IQ2: 45260 | IR2: 45261 | IS2: 45262 | IT2: 45263 | IU2: 45264 | IV2: 45265 | IW2: 45266 | IX2: 45267 | IY2: 45268 | IZ2: 45269 | JA2: 45270 | JB2: 45271 | JC2: 45272 | JD2: 45273 | JE2: 45274 | JF2: 45275 | JG2: 45276 | JH2: 45277 | JI2: 45278 | JJ2: 45279 | JK2: 45280 | JL2: 45281 | JM2: 45282 | JN2: 45283 | JO2: 45284 | JP2: 45285 | JQ2: 45286 | JR2: 45287 | JS2: 45288 | JT2: 45289 | JU2: 45290 | JV2: 45291 | JW2: 45292 | JX2: 45293 | JY2: 45294 | JZ2: 45295 | KA2: 45296 | KB2: 45297 | KC2: 45298 | KD2: 45299 | KE2: 45300 | KF2: 45301 | KG2: 45302 | KH2: 45303 | KI2: 45304 | KJ2: 45305 | KK2: 45306 | KL2: 45307 | KM2: 45308 | KN2: 45309 | KO2: 45310 | KP2: 45311 | KQ2: 45312 | KR2: 45313 | KS2: 45314 | KT2: 45315 | KU2: 45316 | KV2: 45317 | KW2: 45318 | KX2: 45319 | KY2: 45320 | KZ2: 45290 | LA2: 45291 | LB2: 45323 | LC2: 45324 | LD2: 45325 | LE2: 45326 | LF2: 45327 | LG2: 45328 | LH2: 45329 | LI2: 45330 | LJ2: 45331 | LK2: 45332 | LL2: 45333 | LM2: 45334 | LN2: 45335 | LO2: 45336 | LP2: 45337 | LQ2: 45338 | LR2: 45339 | LS2: 45340 | LT2: 45341 | LU2: 45342 | LV2: 45343 | LW2: 45344 | LX2: 45345
C3: 2 | D3: 3 | E3: 4 | F3: 5 | G3: 6 | H3: 7 | I3: CN | J3: 2 | K3: 3 | L3: 4 | M3: 5 | N3: 6 | O3: 7 | P3: CN | Q3: 2 | R3: 3 | S3: 4 | T3: 5 | U3: 6 | V3: 7 | W3: CN | X3: 2 | Y3: 3 | Z3: 4 | AA3: 5 | AB3: 6 | AC3: 7 | AD3: CN | AE3: 2 | AF3: 3 | AG3: 4 | AH3: 5 | AI3: 6 | AJ3: 7 | AK3: CN | AL3: 2 | AM3: 3 | AN3: 4 | AO3: 5 | AP3: 6 | AQ3: 7 | AR3: CN | AS3: 2 | AT3: 3 | AU3: 4 | AV3: 5 | AW3: 6 | AX3: 7 | AY3: CN | AZ3: 2 | BA3: 3 | BB3: 4 | BC3: 5 | BD3: 6 | BE3: 7 | BF3: CN | BG3: 2 | BH3: 3 | BI3: 4 | BJ3: 5 | BK3: 6 | BL3: 7 | BM3: CN | BN3: 2 | BO3: 3 | BP3: 4 | BQ3: 5 | BR3: 6 | BS3: 7 | BT3: CN | BU3: 2 | BV3: 3 | BW3: 4 | BX3: 5 | BY3: 6 | BZ3: 7 | CA3: CN | CB3: 2 | CC3: 3 | CD3: 4 | CE3: 5 | CF3: 6 | CG3: 7 | CH3: CN | CI3: 2 | CJ3: 3 | CK3: 4 | CL3: 5 | CM3: 6 | CN3: 7 | CO3: CN | CP3: 2 | CQ3: 3 | CR3: 4 | CS3: 5 | CT3: 6 | CU3: 7 | CV3: CN | CW3: 2 | CX3: 3 | CY3: 4 | CZ3: 5 | DA3: 6 | DB3: 7 | DC3: CN | DD3: 2 | DE3: 3 | DF3: 4 | DG3: 5 | DH3: 6 | DI3: 7 | DJ3: CN | DK3: 2 | DL3: 3 | DM3: 4 | DN3: 5 | DO3: 6 | DP3: 7 | DQ3: CN | DR3: 2 | DS3: 3 | DT3: 4 | DU3: 5 | DV3: 6 | DW3: 7 | DX3: CN | DY3: 2 | DZ3: 3 | EA3: 4 | EB3: 5 | EC3: 6 | ED3: 7 | EE3: CN | EF3: 2 | EG3: 3 | EH3: 4 | EI3: 5 | EJ3: 6 | EK3: 7 | EL3: CN | EM3: 2 | EN3: 3 | EO3: 4 | EP3: 5 | EQ3: 6 | ER3: 7 | ES3: CN | ET3: 2 | EU3: 3 | EV3: 4 | EW3: 5 | EX3: 6 | EY3: 7 | EZ3: CN | FA3: 2 | FB3: 3 | FC3: 4 | FD3: 5 | FE3: 6 | FF3: 7 | FG3: CN | FH3: 2 | FI3: 3 | FJ3: 4 | FK3: 5 | FL3: 6 | FM3: 7 | FN3: CN | FO3: 2 | FP3: 3 | FQ3: 4 | FR3: 5 | FS3: 6 | FT3: 7 | FU3: CN | FV3: 2 | FW3: 3 | FX3: 4 | FY3: 5 | FZ3: 6 | GA3: 7 | GB3: CN | GC3: 2 | GD3: 3 | GE3: 4 | GF3: 5 | GG3: 6 | GH3: 7 | GI3: CN | GJ3: 2 | GK3: 3 | GL3: 4 | GM3: 5 | GN3: 6 | GO3: 7 | GP3: CN | GQ3: 2 | GR3: 3 | GS3: 4 | GT3: 5 | GU3: 6 | GV3: 7 | GW3: CN | GX3: 2 | GY3: 3 | GZ3: 4 | HA3: 5 | HB3: 6 | HC3: 7 | HD3: CN | HE3: 2 | HF3: 3 | HG3: 4 | HH3: 5 | HI3: 6 | HJ3: 7 | HK3: CN | HL3: 2 | HM3: 3 | HN3: 4 | HO3: 5 | HP3: 6 | HQ3: 7 | HR3: CN | HS3: 2 | HT3: 3 | HU3: 4 | HV3: 5 | HW3: 6 | HX3: 7 | HY3: CN | HZ3: 2 | IA3: 3 | IB3: 4 | IC3: 5 | ID3: 6 | IE3: 7 | IF3: CN | IG3: 2 | IH3: 3 | II3: 4 | IJ3: 5 | IK3: 6 | IL3: 7 | IM3: CN | IN3: 2 | IO3: 3 | IP3: 4 | IQ3: 5 | IR3: 6 | IS3: 7 | IT3: CN | IU3: 2 | IV3: 3 | IW3: 4 | IX3: 5 | IY3: 6 | IZ3: 7 | JA3: CN | JB3: 2 | JC3: 3 | JD3: 4 | JE3: 5 | JF3: 6 | JG3: 7 | JH3: CN | JI3: 2 | JJ3: 3 | JK3: 4 | JL3: 5 | JM3: 6 | JN3: 7 | JO3: CN | JP3: 2 | JQ3: 3 | JR3: 4 | JS3: 5 | JT3: 6 | JU3: 7 | JV3: CN | JW3: 2 | JX3: 3 | JY3: 4 | JZ3: 5 | KA3: 6 | KB3: 7 | KC3: CN | KD3: 2 | KE3: 3 | KF3: 4 | KG3: 5 | KH3: 6 | KI3: 7 | KJ3: CN | KK3: 2 | KL3: 3 | KM3: 4 | KN3: 5 | KO3: 6 | KP3: 7 | KQ3: CN | KR3: 2 | KS3: 3 | KT3: 4 | KU3: 5 | KV3: 6 | KW3: 7 | KX3: CN | KY3: 2 | KZ3: 3 | LA3: 4 | LB3: 5 | LC3: 6 | LD3: 7 | LE3: CN | LF3: 2 | LG3: 3 | LH3: 4 | LI3: 5 | LJ3: 6 | LK3: 7 | LL3: CN | LM3: 2 | LN3: 3 | LO3: 4
A4: Plan vận hành | B4: 1 | C4: Quà Mừng Lễ | AF4: Mâm Cổ Tiến Vua | AU4: Lễ Hội Pháo Hoa | BI4: Gói Nạp Quà Ngày Hè | CJ4: Quà Đoan Ngọ | DN4: Hè Sôi Động (Câu Cá + Đấu Giá Năng Động) | EH4: Thiên Hạ Đệ Nhất Độc | FD4: Giảm Giá Nhận Lại | FL4: ok | GM4: TNTB | HI4: Ưu Đãi Chiêu Mộ Đồng Hành | HZ4: Cổ Mộ Mê Tình | IX4: TNTB | JZ4: TNTB | KD4: Nạp Hoàn Trả | LF4: Event Tết Nguyên Đán
B5: 2 | C5: Pháo Hoa Mừng Lễ | AF5: Lao Động Là Vinh Quang | AU5: Nga Mi Cố Sự | BQ5: Tết Thiếu Nhi | CJ5: Đua Thuyền Rồng | CZ5: TNTB | DG5: Nạp Hoàn Trả | EB5: TNTB | EH5: Pháo Hoa Mừng Lễ | FD5: Quốc Khánh Năng Động | FO5: ok | FY5: Quà Thu Nguyệt | GQ5: Nạp Hoàn Trả | HG5: Đua Top Bang Hội Kỳ Tài Lần II | HW5: Nạp Hoàn Trả | IU5: Nạp Hoàn Trả | JR5: Quà Năm Mới | KH5: Phúc Lộc Tề Thiên
B6: 3 | C6: Pháo Hoa May Mắn | AH6: Quà Tặng Đoàn Kết | AU6: Kết Nghĩa Đào Viên | BQ6: TNTB | CR6: Gói Nạp Quà Hoa Hạ | DU6: Gói Nạp Quà Miêu Lĩnh | EH6: Ưu Đãi Kỳ Trân Các | FD6: Giang Sơn Như Họa | FR6: ok | GE6: Hoạt động Trung Thu | GR6: Ưu Đãi Tết Trùng Thập | HG6: Quà Sơ Đông | HZ6: Ưu Đãi Kỳ Trân Các | JC6: Ưu đãi 12-12 | KM6: Tết Lạp Bát
B7: 4 | Q7: Bảo Thố Chúc Phúc | AH7: Gói Quà Mừng Lễ | AU7: Tích Lũy Nạp Thẻ | BX7: Nạp Hoàn Trả | EH7: Nạp Hoàn Trả | FF7: TNTB | FI7: ok | FK7: Rương Thiên Giáng Hồng Phúc | GZ7: Hoạt động Phụ Nữ Việt Nam | HZ7: Điểm Danh Ngày Lễ | JK7: Chuỗi event giáng sinh | KT7: Quà Tân Xuân
B8: 5 | C8: Hoàng Kim Tài Phú | AU8: Ưu đãi Kỳ Trân Các | FN8: Nạp Hoàn Trả | HN8: Rương Phúc Mãn Nhân Gian | HZ8: Pháo Hoa Mừng Lễ
B9: 6 | CU9: Báo Danh | CX9: Vòng Sơ Tuyển | DI9: Đấu Loại | DL9: Tranh top 8/4 | DT9: Tính năng Người Cũ Trở Về | EP9: Đồng Tâm Kỳ Duyên | FI9: ok | FJ9: Dự Báo VL102 | FO9: Vòng Sơ Tuyển VL102 | GB9: Tổng kết Sơ Tuyển | GF9: Vòng Bán Kết Toàn máy chủ VL102 | GP9: Tổng kết Bán Kết | GT9: Vòng Chung Kết Liên Game VL102 | HD9: Tổng kết Chung Kết | HS9: TNTB | HZ9: Reset X2 Nguyên Bảo | JD9: Vòng Tuyển chọn BHTĐC | JP9: Vòng Tranh Đoạt BHTĐC | JV9: Cổ Vũ Chung Kết
B10: 7 | K10: Rương Phúc Tinh Cao Chiếu | AO10: Ưu đãi Thiệp Chiêu Mộ ĐH | AU10: Môn Phái Mới - Nga Mi | BI10: Tần Thủy Hoàng Lăng | DN10: Bán kết | IH10: Quà Sơ Đông | JW10: Vòng Chung Kết BHTĐC
B11: 8 | S11: Nạp Hoàn Trả | AU11: Di Tích Hàn Vũ (Chưa Mở) | CJ11: Di Tích Hàn Vũ (Mở Thử Nghiệm) | DP11: Chung kết Cụm Hào Kiệt | FF11: Tống Kim-Tháng | FJ11: ok | IK11: Ưu Đãi Black Friday | JX11: T8
B12: 9 | AU12: Tiêu Dao Lục | DQ12: Chung kết Cụm Vô Song | JY12: T4
B13: 10 | AU13: Hệ thống Kết Bái | CU13: GIẢI ĐẤU VÔ SONG HÀO KIỆT | KB13: Bán kết
B14: 11 | AU14: Mở cấp 7x | KC14: Chung kết
A15: Technical | B15: 12 | IU15: Merge sv | IW15: Test API | JK15: Xóa role
B16: 13 | IY16: Trao đổi vấn đề tái đấu vòng tranh đoạt
B17: 14
A18: Data | B18: 15 | IA18: Thời lượng HĐ BOSS | IJ18: Võ luyện | IX18: Thu hồi chìa | JP18: Data SV | KU18: Data Server
B19: 16 | IA19: BXH TPT | JP19: Event tháng (team DATA)
B20: 17 | IA20: Tồn chìa tinh lực
B21: 18 | IB21: Monthly Report | JI21: Monthly Report
A22: MKT | B22: 19 | IC22: Thể lệ Giải Đấu BHTĐC | IW22: Test nhập code (trước 12/12) | JT22: DS VIP | KV22: Gen Code
B23: 20 | IX23: Thưởng giải đấu BHTĐC
B24: 21
A25: Other | B25: 22 | IB25: Rev forecast_VN | IK25: Họp với KS | IW25: Thưởng BHKT | IY25: Checklist giải đấu BHTĐC | JD25: Đánh giá PP | JI25: Event tháng 1 | JM25: Plan BU Bá Đao | JR25: Phương thức vòng quay Tết | KB25: Thông tin PBM | KG25: Event Tết Nguyên Đán | KM25: Event vận hành T2 | KP25: File họp gửi KS
B26: 23 | IC26: Req API khấu trừ item (mục đích Vòng Quay) | IK26: BXH TPT | IX26: Thưởng giải đấu BHTĐC | JD26: Bổ sung thêm đá cho quà mỗi ngày | JK26: API cho KS | JT26: Lôi Đài LSV | KB26: File họp KS | KE26: Thưởng chi tiết Vòng Quay Tết | KR26: MM KS&VNG | KU26: Test Vòng Quay | KZ26: Đánh giá merge
B27: 23 | IQ27: Giải đấu all star | IX27: Gói Quà Năm Mới | KH27: Thưởng chi tiết Gói Xuân Mới | KR27: Test trục 129 | KU27: Checklist BU Bá Đao
B28: 24 | IQ28: Request vòng quay Tết | IW28: BXH giải đấu | IZ28: Giảm giá Phi Phong | KG28: Bổ sung tài nguyên nạp hoàn trả | KU28: Điều chỉnh thưởng Vòng Quay
A30: ĐỊNH KỲ
A31: NGÀY 25/THÁNG | C31: 1. Xuất data server
C32: - 1 sheet là top 50 tài phú của server. 1 sheet là top 10 tài phú bang hội của server
C33: - phần PU k lấy trung bình nữa, mà lấy total PU tương ứng với ngày lấy total rev
C34: 2. Plan event hàng tháng
A35: MỖI THÁNG | C35: Event social TK LSV/TĐMP LSV
C36: Event Bang Hội Kỳ Tài
A37: REV

Sheet 2024
A1: =TODAY() -> 46121 | C1: T1/2024 | AH1: T2/2024 | BK1: T3/2024 | CP1: T4/2024 | DT1: T5/2024 | EY1: T6/2024 | GC1: T7/2024 | HH1: T8/2024 | IM1: T9/2024 | JQ1: T10/2024 | KV1: T11/2024 | LZ1: T12/2024 | NE1: T1/2024
A2: =SUM(C4:ND4) -> 377557 | C2: 45292 | D2: 45293 | E2: 45294 | F2: 45295 | G2: 45296 | H2: 45297 | I2: 45298 | J2: 45299 | K2: 45300 | L2: 45301 | M2: 45302 | N2: 45303 | O2: 45304 | P2: 45305 | Q2: 45306 | R2: 45307 | S2: 45308 | T2: 45309 | U2: 45310 | V2: 45311 | W2: 45312 | X2: 45313 | Y2: 45314 | Z2: 45315 | AA2: 45316 | AB2: 45317 | AC2: 45318 | AD2: 45319 | AE2: 45320 | AF2: 45290 | AG2: 45291 | AH2: 45323 | AI2: 45324 | AJ2: 45325 | AK2: 45326 | AL2: 45327 | AM2: 45328 | AN2: 45329 | AO2: 45330 | AP2: 45331 | AQ2: 45332 | AR2: 45333 | AS2: 45334 | AT2: 45335 | AU2: 45336 | AV2: 45337 | AW2: 45338 | AX2: 45339 | AY2: 45340 | AZ2: 45341 | BA2: 45342 | BB2: 45343 | BC2: 45344 | BD2: 45345 | BE2: 45346 | BF2: 45347 | BG2: 45348 | BH2: 45349 | BI2: 45350 | BJ2: 45351 | BK2: 45352 | BL2: 45353 | BM2: 45354 | BN2: 45355 | BO2: 45356 | BP2: 45357 | BQ2: 45358 | BR2: 45359 | BS2: 45360 | BT2: 45361 | BU2: 45362 | BV2: 45363 | BW2: 45364 | BX2: 45365 | BY2: 45366 | BZ2: 45367 | CA2: 45368 | CB2: 45369 | CC2: 45370 | CD2: 45371 | CE2: 45372 | CF2: 45373 | CG2: 45374 | CH2: 45375 | CI2: 45376 | CJ2: 45377 | CK2: 45378 | CL2: 45379 | CM2: 45380 | CN2: 45381 | CO2: 45382 | CP2: 45383 | CQ2: 45384 | CR2: 45385 | CS2: 45386 | CT2: 45387 | CU2: 45388 | CV2: 45389 | CW2: 45390 | CX2: 45391 | CY2: 45392 | CZ2: 45393 | DA2: 45394 | DB2: 45395 | DC2: 45396 | DD2: 45397 | DE2: 45398 | DF2: 45399 | DG2: 45400 | DH2: 45401 | DI2: 45402 | DJ2: 45403 | DK2: 45404 | DL2: 45405 | DM2: 45406 | DN2: 45407 | DO2: 45408 | DP2: 45409 | DQ2: 45410 | DR2: 45411 | DS2: 45412 | DT2: 45413 | DU2: 45414 | DV2: 45415 | DW2: 45416 | DX2: 45417 | DY2: 45418 | DZ2: 45419 | EA2: 45420 | EB2: 45421 | EC2: 45422 | ED2: 45423 | EE2: 45424 | EF2: 45425 | EG2: 45426 | EH2: 45427 | EI2: 45428 | EJ2: 45429 | EK2: 45430 | EL2: 45431 | EM2: 45432 | EN2: 45433 | EO2: 45434 | EP2: 45435 | EQ2: 45436 | ER2: 45437 | ES2: 45438 | ET2: 45439 | EU2: 45440 | EV2: 45441 | EW2: 45442 | EX2: 45443 | EY2: 45444 | EZ2: 45445 | FA2: 45446 | FB2: 45447 | FC2: 45448 | FD2: 45449 | FE2: 45450 | FF2: 45451 | FG2: 45452 | FH2: 45453 | FI2: 45454 | FJ2: 45455 | FK2: 45456 | FL2: 45457 | FM2: 45458 | FN2: 45459 | FO2: 45460 | FP2: 45461 | FQ2: 45462 | FR2: 45463 | FS2: 45464 | FT2: 45465 | FU2: 45466 | FV2: 45467 | FW2: 45468 | FX2: 45469 | FY2: 45470 | FZ2: 45471 | GA2: 45472 | GB2: 45473 | GC2: 45474 | GD2: 45475 | GE2: 45476 | GF2: 45477 | GG2: 45478 | GH2: 45479 | GI2: 45480 | GJ2: 45481 | GK2: 45482 | GL2: 45483 | GM2: 45484 | GN2: 45485 | GO2: 45486 | GP2: 45487 | GQ2: 45488 | GR2: 45489 | GS2: 45490 | GT2: 45491 | GU2: 45492 | GV2: 45493 | GW2: 45494 | GX2: 45495 | GY2: 45496 | GZ2: 45497 | HA2: 45498 | HB2: 45499 | HC2: 45500 | HD2: 45501 | HE2: 45502 | HF2: 45503 | HG2: 45504 | HH2: 45505 | HI2: 45506 | HJ2: 45507 | HK2: 45508 | HL2: 45509 | HM2: 45510 | HN2: 45511 | HO2: 45512 | HP2: 45513 | HQ2: 45514 | HR2: 45515 | HS2: 45516 | HT2: 45517 | HU2: 45518 | HV2: 45519 | HW2: 45520 | HX2: 45521 | HY2: 45522 | HZ2: 45523 | IA2: 45524 | IB2: 45525 | IC2: 45526 | ID2: 45527 | IE2: 45528 | IF2: 45529 | IG2: 45530 | IH2: 45531 | II2: 45532 | IJ2: 45533 | IK2: 45534 | IL2: 45535 | IM2: 45536 | IN2: 45537 | IO2: 45538 | IP2: 45539 | IQ2: 45540 | IR2: 45541 | IS2: 45542 | IT2: 45543 | IU2: 45544 | IV2: 45545 | IW2: 45546 | IX2: 45547 | IY2: 45548 | IZ2: 45549 | JA2: 45550 | JB2: 45551 | JC2: 45552 | JD2: 45553 | JE2: 45554 | JF2: 45555 | JG2: 45556 | JH2: 45557 | JI2: 45558 | JJ2: 45559 | JK2: 45560 | JL2: 45561 | JM2: 45562 | JN2: 45563 | JO2: 45564 | JP2: 45565 | JQ2: 45566 | JR2: 45567 | JS2: 45568 | JT2: 45569 | JU2: 45570 | JV2: 45571 | JW2: 45572 | JX2: 45573 | JY2: 45574 | JZ2: 45575 | KA2: 45576 | KB2: 45577 | KC2: 45578 | KD2: 45579 | KE2: 45580 | KF2: 45581 | KG2: 45582 | KH2: 45583 | KI2: 45584 | KJ2: 45585 | KK2: 45586 | KL2: 45587 | KM2: 45588 | KN2: 45589 | KO2: 45590 | KP2: 45591 | KQ2: 45592 | KR2: 45593 | KS2: 45594 | KT2: 45595 | KU2: 45596 | KV2: 45597 | KW2: 45598 | KX2: 45599 | KY2: 45600 | KZ2: 45601 | LA2: 45602 | LB2: 45603 | LC2: 45604 | LD2: 45605 | LE2: 45606 | LF2: 45607 | LG2: 45608 | LH2: 45609 | LI2: 45610 | LJ2: 45611 | LK2: 45612 | LL2: 45613 | LM2: 45614 | LN2: 45615 | LO2: 45616 | LP2: 45617 | LQ2: 45618 | LR2: 45619 | LS2: 45620 | LT2: 45621 | LU2: 45622 | LV2: 45623 | LW2: 45624 | LX2: 45625 | LY2: 45626 | LZ2: 45627 | MA2: 45628 | MB2: 45629 | MC2: 45630 | MD2: 45631 | ME2: 45632 | MF2: 45633 | MG2: 45634 | MH2: 45635 | MI2: 45636 | MJ2: 45637 | MK2: 45638 | ML2: 45639 | MM2: 45640 | MN2: 45641 | MO2: 45642 | MP2: 45643 | MQ2: 45644 | MR2: 45645 | MS2: 45646 | MT2: 45647 | MU2: 45648 | MV2: 45649 | MW2: 45650 | MX2: 45651 | MY2: 45652 | MZ2: 45653 | NA2: 45654 | NB2: 45655 | NC2: 45656 | ND2: 45657 | NE2: 45658 | NF2: 45659 | NG2: 45660 | NH2: 45661 | NI2: 45662 | NJ2: 45663 | NK2: 45664 | NL2: 45665 | NM2: 45666 | NN2: 45667 | NO2: 45668 | NP2: 45669 | NQ2: 45670 | NR2: 45671 | NS2: 45672 | NT2: 45673 | NU2: 45674 | NV2: 45675 | NW2: 45676 | NX2: 45677 | NY2: 45678 | NZ2: 45679 | OA2: 45680 | OB2: 45681 | OC2: 45682 | OD2: 45683 | OE2: 45684 | OF2: 45685 | OG2: 45686 | OH2: 45687 | OI2: 45688 | OJ2: 45689 | OK2: 45690 | OL2: 45691 | OM2: 45692 | ON2: 45693 | OO2: 45694 | OP2: 45695 | OQ2: 45696 | OR2: 45697 | OS2: 45698
A3: =A2/554387 -> 0.68103509 | C3: 2 | D3: 3 | E3: 4 | F3: 5 | G3: 6 | H3: 7 | I3: CN | J3: 2 | K3: 3 | L3: 4 | M3: 5 | N3: 6 | O3: 7 | P3: CN | Q3: 2 | R3: 3 | S3: 4 | T3: 5 | U3: 6 | V3: 7 | W3: CN | X3: 2 | Y3: 3 | Z3: 4 | AA3: 5 | AB3: 6 | AC3: 7 | AD3: CN | AE3: 2 | AF3: 3 | AG3: 4 | AH3: 5 | AI3: 6 | AJ3: 7 | AK3: CN | AL3: 2 | AM3: 3 | AN3: 4 | AO3: 5 | AP3: 6 | AQ3: 7 | AR3: CN | AS3: 2 | AT3: 3 | AU3: 4 | AV3: 5 | AW3: 6 | AX3: 7 | AY3: CN | AZ3: 2 | BA3: 3 | BB3: 4 | BC3: 5 | BD3: 6 | BE3: 7 | BF3: CN | BG3: 2 | BH3: 3 | BI3: 4 | BJ3: 5 | BK3: 6 | BL3: 7 | BM3: CN | BN3: 2 | BO3: 3 | BP3: 4 | BQ3: 5 | BR3: 6 | BS3: 7 | BT3: CN | BU3: 2 | BV3: 3 | BW3: 4 | BX3: 5 | BY3: 6 | BZ3: 7 | CA3: CN | CB3: 2 | CC3: 3 | CD3: 4 | CE3: 5 | CF3: 6 | CG3: 7 | CH3: CN | CI3: 2 | CJ3: 3 | CK3: 4 | CL3: 5 | CM3: 6 | CN3: 7 | CO3: CN | CP3: 2 | CQ3: 3 | CR3: 4 | CS3: 5 | CT3: 6 | CU3: 7 | CV3: CN | CW3: 2 | CX3: 3 | CY3: 4 | CZ3: 5 | DA3: 6 | DB3: 7 | DC3: CN | DD3: 2 | DE3: 3 | DF3: 4 | DG3: 5 | DH3: 6 | DI3: 7 | DJ3: CN | DK3: 2 | DL3: 3 | DM3: 4 | DN3: 5 | DO3: 6 | DP3: 7 | DQ3: CN | DR3: 2 | DS3: 3 | DT3: 4 | DU3: 5 | DV3: 6 | DW3: 7 | DX3: CN | DY3: 2 | DZ3: 3 | EA3: 4 | EB3: 5 | EC3: 6 | ED3: 7 | EE3: CN | EF3: 2 | EG3: 3 | EH3: 4 | EI3: 5 | EJ3: 6 | EK3: 7 | EL3: CN | EM3: 2 | EN3: 3 | EO3: 4 | EP3: 5 | EQ3: 6 | ER3: 7 | ES3: CN | ET3: 2 | EU3: 3 | EV3: 4 | EW3: 5 | EX3: 6 | EY3: 7 | EZ3: CN | FA3: 2 | FB3: 3 | FC3: 4 | FD3: 5 | FE3: 6 | FF3: 7 | FG3: CN | FH3: 2 | FI3: 3 | FJ3: 4 | FK3: 5 | FL3: 6 | FM3: 7 | FN3: CN | FO3: 2 | FP3: 3 | FQ3: 4 | FR3: 5 | FS3: 6 | FT3: 7 | FU3: CN | FV3: 2 | FW3: 3 | FX3: 4 | FY3: 5 | FZ3: 6 | GA3: 7 | GB3: CN | GC3: 2 | GD3: 3 | GE3: 4 | GF3: 5 | GG3: 6 | GH3: 7 | GI3: CN | GJ3: 2 | GK3: 3 | GL3: 4 | GM3: 5 | GN3: 6 | GO3: 7 | GP3: CN | GQ3: 2 | GR3: 3 | GS3: 4 | GT3: 5 | GU3: 6 | GV3: 7 | GW3: CN | GX3: 2 | GY3: 3 | GZ3: 4 | HA3: 5 | HB3: 6 | HC3: 7 | HD3: CN | HE3: 2 | HF3: 3 | HG3: 4 | HH3: 5 | HI3: 6 | HJ3: 7 | HK3: CN | HL3: 2 | HM3: 3 | HN3: 4 | HO3: 5 | HP3: 6 | HQ3: 7 | HR3: CN | HS3: 2 | HT3: 3 | HU3: 4 | HV3: 5 | HW3: 6 | HX3: 7 | HY3: CN | HZ3: 2 | IA3: 3 | IB3: 4 | IC3: 5 | ID3: 6 | IE3: 7 | IF3: CN | IG3: 2 | IH3: 3 | II3: 4 | IJ3: 5 | IK3: 6 | IL3: 7 | IM3: CN | IN3: 2 | IO3: 3 | IP3: 4 | IQ3: 5 | IR3: 6 | IS3: 7 | IT3: CN | IU3: 2 | IV3: 3 | IW3: 4 | IX3: 5 | IY3: 6 | IZ3: 7 | JA3: CN | JB3: 2 | JC3: 3 | JD3: 4 | JE3: 5 | JF3: 6 | JG3: 7 | JH3: CN | JI3: 2 | JJ3: 3 | JK3: 4 | JL3: 5 | JM3: 6 | JN3: 7 | JO3: CN | JP3: 2 | JQ3: 3 | JR3: 4 | JS3: 5 | JT3: 6 | JU3: 7 | JV3: CN | JW3: 2 | JX3: 3 | JY3: 4 | JZ3: 5 | KA3: 6 | KB3: 7 | KC3: CN | KD3: 2 | KE3: 3 | KF3: 4 | KG3: 5 | KH3: 6 | KI3: 7 | KJ3: CN | KK3: 2 | KL3: 3 | KM3: 4 | KN3: 5 | KO3: 6 | KP3: 7 | KQ3: CN | KR3: 2 | KS3: 3 | KT3: 4 | KU3: 5 | KV3: 6 | KW3: 7 | KX3: CN | KY3: 2 | KZ3: 3 | LA3: 4 | LB3: 5 | LC3: 6 | LD3: 7 | LE3: CN | LF3: 2 | LG3: 3 | LH3: 4 | LI3: 5 | LJ3: 6 | LK3: 7 | LL3: CN | LM3: 2 | LN3: 3 | LO3: 4 | LP3: 5 | LQ3: 6 | LR3: 7 | LS3: CN | LT3: 2 | LU3: 3 | LV3: 4 | LW3: 5 | LX3: 6 | LY3: 7 | LZ3: CN | MA3: 2 | MB3: 3 | MC3: 4 | MD3: 5 | ME3: 6 | MF3: 7 | MG3: CN | MH3: 2 | MI3: 3 | MJ3: 4 | MK3: 5 | ML3: 6 | MM3: 7 | MN3: CN | MO3: 2 | MP3: 3 | MQ3: 4 | MR3: 5 | MS3: 6 | MT3: 7 | MU3: CN | MV3: 2 | MW3: 3 | MX3: 4 | MY3: 5 | MZ3: 6 | NA3: 7 | NB3: CN | NC3: 2 | ND3: 3 | NE3: 4 | NF3: 5 | NG3: 6 | NH3: 7 | NI3: CN | NJ3: 2 | NK3: 3 | NL3: 4 | NM3: 5 | NN3: 6 | NO3: 7 | NP3: CN | NQ3: 2 | NR3: 3 | NS3: 4 | NT3: 5 | NU3: 6 | NV3: 7 | NW3: CN | NX3: 2 | NY3: 3 | NZ3: 4 | OA3: 5 | OB3: 6 | OC3: 7 | OD3: CN | OE3: 2 | OF3: 3 | OG3: 4 | OH3: 5 | OI3: 6 | OJ3: 7 | OK3: CN | OL3: 2 | OM3: 3 | ON3: 4 | OO3: 5 | OP3: 6 | OQ3: 7 | OR3: CN | OS3: 2
A4: REV(M) | C4: =ROUND(REV!B2/1000000,0) -> 1020 | D4: =ROUND(REV!C2/1000000,0) -> 1167 | E4: =ROUND(REV!D2/1000000,0) -> 831 | F4: =ROUND(REV!E2/1000000,0) -> 1386 | G4: =ROUND(REV!F2/1000000,0) -> 1061 | H4: =ROUND(REV!G2/1000000,0) -> 1224 | I4: =ROUND(REV!H2/1000000,0) -> 908 | J4: =ROUND(REV!I2/1000000,0) -> 2873 | ... ND4: =ROUND(REV!NC2/1000000,0) -> 765
A5: Plan vận hành | B5: 1 | F5: TNTB | J5: Nạp Hoàn Trả | AG5: Vượt Vũ Môn (H5) | BI5: Dương Đao Đại Hội | CY5: Event Giỗ Tổ | EA5: TNTB | EF5: Trợ Uy Vô Song | EV5: Số Tay Tuổi Thơ | FN5: Quà Mùa Hè (1.72B, 2k5 PU) | GJ5: TNTB (0.93B, 1k4 PU) | GS5: Event Câu Cá (950M, PU 2k7 PU) | HK5: TNTB (0.98B, 1k4 PU) | HU5: Ưu Đãi Thất Tịch (1.3B, 5.1K PU) | IO5: Nạp Hoàn Trả | JF5: Quà Thu Nguyệt (2.1B, 2.7K PU) | KA5: Thần Thạch Bí Ẩn (2.6B, 4.3K PU) (68tr NB, 17K role) | KX5: TNTB (1.3B, 1.3K PU) | LF5: Ưu Đãi 11-11 | LN5: Quà Tôn Sư (1.7B, 2.4K PU) | MC5: sơ tuyển (1.7B, 3.6K PU) | MK5: Đấu thử | MM5: Top32 | MO5: Top16 | MQ5: Top8 | MS5: Tứ Kết | MU5: Bán Kết | MV5: Quà Tân Niên (2B, 3.6K PU) | NJ5: TNTB | NY5: Promotion Tết
B6: 2 | N6: Rương Phúc Lộc Tề Thiên | AH6: Tài Vận Hanh Thông | BD6: Đố Đèn | BI6: Tái Xuất Giang Hồ | CE6: Vòng quay sinh nhật (5.4B, 2.9K PU) | DB6: Ưu đãi Mừng Lễ | DT6: Nạp Hoàn Trả | EV6: Công Viên Giải Trí (2B) (3.7K PU) | FQ6: Càn Quét Mùa Hè (2tr4 KL, 78tr3 NB) (600M) | GE6: Vui Cùng Euro (2.6B, 2.4K PU) | HA6: Rương Trân Bảo Ngày Hạ (1.8B, 4k2 PU) | HO6: Thất Tịch (Tầm Duyên) (2.3B, 1k1 PU) (90tr NB, 21.5K role) | ID6: Vòng Quay Đại Lễ (2.8B, 3.4K PU) | IR6: TNTB (1.2B, 1.3K PU) | JL6: Tầm Duyên (2.5B, 2.6K PU) (91tr NB, 21.3K role) | KF6: 西毒现世-Bạch Đà Hiện Thế (1.6B, 2k PU) | KV6: Nạp Hoàn Trả | LT6: Tầm Duyên (2.56B, 2.6K PU) | MK6: Ưu Đãi 12-12 | MU6: Chung Kết | NG6: Nạp Hoàn Trả
B7: 3 | S7: Tết Lạp Bát | AK7: Tân Xuân Chung Vui | BD7: Mỹ Vị NT | BI7: Lễ Hội Pháo Hoa | CK7: Event sinh nhật | DG7: Quà Mừng Lễ | DW7: Rương Phú Quý Cát Tường (708M, 2K PU) | EJ7: Quà Mùa Hạ | EV7: Thổi Bong Bóng | FX7: 逍遥自在_Tiêu Diêu Tự Tại (2.6B, 6.7K PU) | GU7: Quà Hạ Vũ (1.73B, 2k7 PU) | HH7: Nạp Hoàn Trả | HY7: Quà Thất Tịch (2.5B, 3.1K PU) | IR7: Ghi Danh và Thông Báo Giải Đấu Nhất Kiếm Kinh Thiên | JB7: Rương Nhất Kiếm Quang Vinh (1.7B, 5.2K PU) | JV7: TNTB (1.5B, 1.4K PU) | KF7: 奇珍阁特惠-Ưu Đãi KTC (1.7B, 5k PU) (218tr NB) | LC7: Rương Tường Vân Đại Cát (2.35B, 5.1k PU) | MA7: Nạp Hoàn Trả | NE7: Ưu Đãi 01-01 | NN7: Khởi Niên Tầm Duyên
B8: 4 | Z8: Quà Tân Xuân | AP8: Lì Xì Phúc Vận | BD8: Tiệc NT | BI8: Ưu đãi Kỳ Trân Các | BW8: Rương Phúc Đại Viên Mãn | DO8: 庆典转盘_Vòng Quay Mừng Lễ | EM8: Tầm Duyên Mùa Hạ (1.1B) | FC8: Đua Thuyền Rồng | FX8: 奇珍阁特惠_Ưu đãi Kỳ Trân Các (1.6B, 4k6 PU) (170tr NB) | HE8: Thiên Y Các (400M, 1k1PU) | HU8: Thần Tài Phát Lộc | IH8: Vòng Quay Webshop | IR8: Nhất Kiếm Chiêu Anh (700tr, 2.4k PU) | JC8: Vòng Loại | JI8: Dự Đoán | KF8: 再闯江湖-Tái Xuất Giang Hồ | LH8: Bức Họa Sư Đồ | LX8: Black Friday (743M, 2.8K PU) | MH8: Thần Thạch Bí Ẩn (2.3B, 3.9K PU) | MZ8: Rương Ất Tỵ Phú Quý (1.6B, 4.2K PU) | NT8: Quà Khai Xuân
B9: 5 | AK9: Ưu Đãi Nhận Lại | BI9: Reset X2 Nguyên Bảo | CP9: Nạp Hoàn Trả | DO9: 劳动节活动系列_Chuỗi event Lễ Lao Động | EF9: Giải đấu Vô Song Hào Kiệt | FC9: Quà Đoan Ngọ (1.3B) (3.1K PU) | FX9: 再闯江湖Tái Xuất Giang Hồ | HO9: Thất Tịch-Vì Yêu | IV9: Vòng Sơ Tuyển | JJ9: Top 32 | JK9: Top 8 | JL9: Tứ Kết | JO9: Bán Kết | KF9: 首充双倍-Reset x2 nạp đầu | LH9: Tri Ân Sư Đồ (1.6B, 4.2K PU) | MD9: TNTB (1.2B. 1.3K PU) | MQ9: Dạ Lan Quan
B10: 6 | AP10: Tiệc Tất Niên | BI10: Quà Tặng Phiên Bản | CS10: TNTB | EF10: Báo Danh | FC10: Búp Bê Hoài Cổ | FX10: 重置首次充值双_Reset X2 Nguyên Bảo | HO10: Thất Tịch-Ưu Đãi Giới Hạn | JJ10: Top 16 | JO10: Chung Kết | KF10: 资料片礼物-Quà Mừng PBM | LH10: Quà Sư Đồ (2B, 4K PU) | MQ10: Tuyết Ngày Đông
B11: 7 | AJ11: TNTB | AP11: Niên Thú | AU11: Tâm Đầu Ý Hợp (Valentine) | BA11: Quà Du Xuân | BR11: TNTB | CB11: Quà Đầu Hạ | EI11: Sơ Tuyển | FC11: Kẻ Trộm Thanh Xuân | FX11: 资料片礼物_Quà Tặng Phiên Bản | IJ11: Giang Sơn Như Họa (1.1B, 4k PU) | IW11: Quà Tặng Thân Tình (1.3B, 3.2K PU) | KF11: 烟花庆典-Pháo Hoa Mừng Lễ | LH11: Đại Chiến Bãi Biển | MQ11: Trang Trí Giáng Sinh (1.8B, 4.8K PU)
B12: 8 | AP12: Đếm ngược Tân Xuân | AU12: Ưu đãi (Valentine) | BN12: Nạp Hoàn Trả | ES12: Đấu Loại | EV12: Dự Đoán | FC12: Đoan Ngọ Gói Bánh (1.6B) | FX12: 烟花庆典-Pháo Hoa Mừng Lễ | IJ12: Thần Thạch Huyền Bí (1.9B, 11k PU) | IW12: Tiệc Đoàn Viên | JR12: Nạp Hoàn Trả | KO12: Quà Sơ Đông (2B, 2.7k PU) | LP12: Bằng Hữu Hiệp Lực (Promotion mời bạn) | MQ12: Hộp Quà Giáng Sinh (1.8B, 3.5K PU)
B13: 9 | AP13: Hoạt Động Cuối Tuần | BI13: Bá Đao | BQ13: Ưu đãi 8-3 | EV13: Top 8 | FA13: Nạp Hoàn Trả | GE13: Nạp Hoàn Trả | IJ13: Giảm giá nhận lại | IW13: Hộp Quà Trung Thu (2.5B, 2.7K PU) | JS13: Bang Hội Kỳ Tài | KT13: Promotion Vòng Quay Săn Quà Bí Ngô (2.8B, 3.2k PU) | LH13: Update phúc lợi mỗi ngày (thẻ tuần/tháng, online, điểm danh, rương HK)
B14: 10 | AO14: Nạp Hoàn Trả | BI14: Kinh mạch | EV14: Top 4 | FH14: TNTB | IJ14: Quốc Khánh Năng Động | IW14: Thỏ Ngọc Ủ Rượu | KK14: Thiên Y Các | LH14: Tăng exp cơ bản từ pb/hđ
B15: 11 | BI15: Thiên Tầng Tháp | EW15: Bán Kết | EY15: Chung Kết | FM15: Vòng Loại Euro 2024 | GA15: Top 8 EU | GG15: Tứ Kết EU | GL15: Bán Kết | GQ15: Chung Kết | IJ15: Ưu đãi cuối tuần | KF15: Phái Bạch Đà | KT15: Bổ sung nguồn ra free đột phá kỹ năng từ trục lv169
A16: Technical | B16: 12 | BI16: Map LSV KTH | DE16: Ticket API vòng quay mừng lễ | DS16: Điều chỉnh zonemapping | KF16: Kỹ Năng Thú Cưỡi
B17: 13 | BI17: Vận Tiêu KTH | KF17: Lâu Lan Mê Tung
B18: 14 | KF18: Song Vực Tranh Phong
A19: Data | B19: 15 | BA19: Dánh sách merge | CI19: Dánh sách merge | CZ19: Check phân loại gói nạp | ET19: Data merge | KF19: Xếp Hạng Võ Hàm
B20: 16 | CZ20: Check phân loại item - TA | KF20: Cân bằng hệ phái
B21: 17
B22: 18
A23: MKT | B23: 19 | BA23: Storekit | BW23: Vô Song Hào Kiệt | CS23: Đánh giá Tái Xuất Giang Hồ | DA23: Nội dung Ưu đãi Mừng Lễ - TA | DH23: Plan T5 (full) | DO23: Plan BU T6 | DW23: Giải đấu đồng lực chiến | EC23: Giải đấu Việt-Trung | EU23: Store kit | FS23: RP hiệu quả các giải đấu trước đây
B24: 20 | BA24: Submit | DE24: Plan nửa đầu T5 | DO24: Code T5 | ET24: Bảng đấu 16 đội
B26: 21 | BB26: Cụ thể Plan 2024 | DH26: Thưởng sân chơi social
A27: Other | B27: 22 | BB27: RP Vượt Vũ Môn | BW27: Đánh giá mở dòng 2 Kinh Mạch | BZ27: Test TW | CB27: Vòng quay sinh nhật | CR27: Req Promotion Vòng Quay Mừng Lễ | DE27: FB điều chỉnh kỹ năng | DN27: FB EV Đoan Ngọ | DV27: Timeline update & lên tin Kinh Mạch | ET27: Chốt ngoại quan đồng bộ trong BU | FL27: RP họp định kỳ T6 | HC27: File giải đấu Việt Trung
B28: 23 | BW28: Edit event Thanh Minh -> Giỗ Tổ | BZ28: Điều tra thằng nạp 50K 300 lần | CU28: Thưởng Vòng Quay Mừng Lễ | CZ28: Check data bày bán | DA28: Giải pháp cho user drop | DZ28: Hỗ trợ VIP ở sv mới | FJ28: Plan nửa đầu T7
B29: 23 | BW29: Bổ sung thưởng event Sinh Nhật | CU29: Điều chỉnh text Bảo Vệ Hồn Tổ Tiên | DA29: Fix hoàn sao lãnh thổ | DE29: Gửi đối tác data bị thiếu Tháng 2 | EI29: Ưu hóa cấp độ | FK29: RP T5 cho đối tác
B30: 24 | BW30: Test thưởng vòng quay Sinh Nhật | BZ30: Code report | CU30: Ưu hóa mở rộng Kinh Mạch | DA30: FB EV 1-6 | DD30: Gửi đối tác data bị thiếu tuần 9-10/4 | FR30: File họp đối tác
B31: 24 | BW31: Plan T4 | BY31: Đánh giá lại Vận Tiêu và nguồn sinh Kinh Mạch | CU31: Đánh giá BU | DA31: Đền bù nạp (retry thành công, thất bại)
BI32: BÁ ĐAO | FX32: Tiêu Dao
A33: ĐỊNH KỲ | FX33: Trang Bị Đồng Hành
A34: NGÀY 25/THÁNG | C34: 1. Xuất data server | FX34: Hãn Hải Mật Thành
C35: - 1 sheet là top 50 tài phú của server. 1 sheet là top 10 tài phú bang hội của server | FX35: Hiệp Lữ
C36: - phần PU k lấy trung bình nữa, mà lấy total PU tương ứng với ngày lấy total rev | FX36: Bộ kỹ năng lv90
C37: 2. Plan event hàng tháng
C38: 3. Hỗ trợ hàng tháng trong tuần có ngày 25
A39: MỖI THÁNG | C39: Event social TK LSV/TĐMP LSV

Sheet 2025
A1: =TODAY() -> 46121 | C1: T1/2025 | AH1: T2/2025 | BJ1: T3/2025 | CO1: T4/2025 | DS1: T5/2025 | EX1: T6/2025 | GB1: T7/2025 | HG1: T8/2025 | IL1: T9/2025 | JP1: T10/2025 | KU1: T11/2025 | LY1: T12/2025
A2: =SUM(C4:NC4) -> 316124 | C2: 45658 | D2: 45659 | E2: 45660 | F2: 45661 | G2: 45662 | H2: 45663 | I2: 45664 | J2: 45665 | K2: 45666 | L2: 45667 | M2: 45668 | N2: 45669 | O2: 45670 | P2: 45671 | Q2: 45672 | R2: 45673 | S2: 45674 | T2: 45675 | U2: 45676 | V2: 45677 | W2: 45678 | X2: 45679 | Y2: 45680 | Z2: 45681 | AA2: 45682 | AB2: 45683 | AC2: 45684 | AD2: 45685 | AE2: 45686 | AF2: 45687 | AG2: 45688 | AH2: 45689 | AI2: 45690 | AJ2: 45691 | AK2: 45692 | AL2: 45693 | AM2: 45694 | AN2: 45695 | AO2: 45696 | AP2: 45697 | AQ2: 45698 | AR2: 45699 | AS2: 45700 | AT2: 45701 | AU2: 45702 | AV2: 45703 | AW2: 45704 | AX2: 45705 | AY2: 45706 | AZ2: 45707 | BA2: 45708 | BB2: 45709 | BC2: 45710 | BD2: 45711 | BE2: 45712 | BF2: 45713 | BG2: 45714 | BH2: 45715 | BI2: 45716 | BJ2: 45717 | BK2: 45718 | BL2: 45719 | BM2: 45720 | BN2: 45721 | BO2: 45722 | BP2: 45723 | BQ2: 45724 | BR2: 45725 | BS2: 45726 | BT2: 45727 | BU2: 45728 | BV2: 45729 | BW2: 45730 | BX2: 45731 | BY2: 45732 | BZ2: 45733 | CA2: 45734 | CB2: 45735 | CC2: 45736 | CD2: 45737 | CE2: 45738 | CF2: 45739 | CG2: 45740 | CH2: 45741 | CI2: 45742 | CJ2: 45743 | CK2: 45744 | CL2: 45745 | CM2: 45746 | CN2: 45747 | CO2: 45748 | CP2: 45749 | CQ2: 45750 | CR2: 45751 | CS2: 45752 | CT2: 45753 | CU2: 45754 | CV2: 45755 | CW2: 45756 | CX2: 45757 | CY2: 45758 | CZ2: 45759 | DA2: 45760 | DB2: 45761 | DC2: 45762 | DD2: 45763 | DE2: 45764 | DF2: 45765 | DG2: 45766 | DH2: 45767 | DI2: 45768 | DJ2: 45769 | DK2: 45770 | DL2: 45771 | DM2: 45772 | DN2: 45773 | DO2: 45774 | DP2: 45775 | DQ2: 45776 | DR2: 45777 | DS2: 45778 | DT2: 45779 | DU2: 45780 | DV2: 45781 | DW2: 45782 | DX2: 45783 | DY2: 45784 | DZ2: 45785 | EA2: 45786 | EB2: 45787 | EC2: 45788 | ED2: 45789 | EE2: 45790 | EF2: 45791 | EG2: 45792 | EH2: 45793 | EI2: 45794 | EJ2: 45795 | EK2: 45796 | EL2: 45797 | EM2: 45798 | EN2: 45799 | EO2: 45800 | EP2: 45801 | EQ2: 45802 | ER2: 45803 | ES2: 45804 | ET2: 45805 | EU2: 45806 | EV2: 45807 | EW2: 45808 | EX2: 45809 | EY2: 45810 | EZ2: 45811 | FA2: 45812 | FB2: 45813 | FC2: 45814 | FD2: 45815 | FE2: 45816 | FF2: 45817 | FG2: 45818 | FH2: 45819 | FI2: 45820 | FJ2: 45821 | FK2: 45822 | FL2: 45823 | FM2: 45824 | FN2: 45825 | FO2: 45826 | FP2: 45827 | FQ2: 45828 | FR2: 45829 | FS2: 45830 | FT2: 45831 | FU2: 45832 | FV2: 45833 | FW2: 45834 | FX2: 45835 | FY2: 45836 | FZ2: 45837 | GA2: 45838 | GB2: 45839 | GC2: 45840 | GD2: 45841 | GE2: 45842 | GF2: 45843 | GG2: 45844 | GH2: 45845 | GI2: 45846 | GJ2: 45847 | GK2: 45848 | GL2: 45849 | GM2: 45850 | GN2: 45851 | GO2: 45852 | GP2: 45853 | GQ2: 45854 | GR2: 45855 | GS2: 45856 | GT2: 45857 | GU2: 45858 | GV2: 45859 | GW2: 45860 | GX2: 45861 | GY2: 45862 | GZ2: 45863 | HA2: 45864 | HB2: 45865 | HC2: 45866 | HD2: 45867 | HE2: 45868 | HF2: 45869 | HG2: 45870 | HH2: 45871 | HI2: 45872 | HJ2: 45873 | HK2: 45874 | HL2: 45875 | HM2: 45876 | HN2: 45877 | HO2: 45878 | HP2: 45879 | HQ2: 45880 | HR2: 45881 | HS2: 45882 | HT2: 45883 | HU2: 45884 | HV2: 45885 | HW2: 45886 | HX2: 45887 | HY2: 45888 | HZ2: 45889 | IA2: 45890 | IB2: 45891 | IC2: 45892 | ID2: 45893 | IE2: 45894 | IF2: 45895 | IG2: 45896 | IH2: 45897 | II2: 45898 | IJ2: 45899 | IK2: 45900 | IL2: 45901 | IM2: 45902 | IN2: 45903 | IO2: 45904 | IP2: 45905 | IQ2: 45906 | IR2: 45907 | IS2: 45908 | IT2: 45909 | IU2: 45910 | IV2: 45911 | IW2: 45912 | IX2: 45913 | IY2: 45914 | IZ2: 45915 | JA2: 45916 | JB2: 45917 | JC2: 45918 | JD2: 45919 | JE2: 45920 | JF2: 45921 | JG2: 45922 | JH2: 45923 | JI2: 45924 | JJ2: 45925 | JK2: 45926 | JL2: 45927 | JM2: 45928 | JN2: 45929 | JO2: 45930 | JP2: 45931 | JQ2: 45932 | JR2: 45933 | JS2: 45934 | JT2: 45935 | JU2: 45936 | JV2: 45937 | JW2: 45938 | JX2: 45939 | JY2: 45940 | JZ2: 45941 | KA2: 45942 | KB2: 45943 | KC2: 45944 | KD2: 45945 | KE2: 45946 | KF2: 45947 | KG2: 45948 | KH2: 45949 | KI2: 45950 | KJ2: 45951 | KK2: 45952 | KL2: 45953 | KM2: 45954 | KN2: 45955 | KO2: 45956 | KP2: 45957 | KQ2: 45958 | KR2: 45959 | KS2: 45960 | KT2: 45961 | KU2: 45962 | KV2: 45963 | KW2: 45964 | KX2: 45965 | KY2: 45966 | KZ2: 45967 | LA2: 45968 | LB2: 45969 | LC2: 45970 | LD2: 45971 | LE2: 45972 | LF2: 45973 | LG2: 45974 | LH2: 45975 | LI2: 45976 | LJ2: 45977 | LK2: 45978 | LL2: 45979 | LM2: 45980 | LN2: 45981 | LO2: 45982 | LP2: 45983 | LQ2: 45984 | LR2: 45985 | LS2: 45986 | LT2: 45987 | LU2: 45988 | LV2: 45989 | LW2: 45990 | LX2: 45991 | LY2: 45992 | LZ2: 45993 | MA2: 45994 | MB2: 45995 | MC2: 45996 | MD2: 45997 | ME2: 45998 | MF2: 45999 | MG2: 46000 | MH2: 46001 | MI2: 46002 | MJ2: 46003 | MK2: 46004 | ML2: 46005 | MM2: 46006 | MN2: 46007 | MO2: 46008 | MP2: 46009 | MQ2: 46010 | MR2: 46011 | MS2: 46012 | MT2: 46013 | MU2: 46014 | MV2: 46015 | MW2: 46016 | MX2: 46017 | MY2: 46018 | MZ2: 46019 | NA2: 46020 | NB2: 46021 | NC2: 46022 | ND2: 46023 | NE2: 46024 | NF2: 46025 | NG2: 46026 | NH2: 46027 | NI2: 46028 | NJ2: 46029 | NK2: 46030
A3: =A2/260288 -> 1.2145162 | C3: 4 | D3: 5 | E3: 6 | F3: 7 | G3: CN | H3: 2 | I3: 3 | J3: 4 | K3: 5 | L3: 6 | M3: 7 | N3: CN | O3: 2 | P3: 3 | Q3: 4 | R3: 5 | S3: 6 | T3: 7 | U3: CN | V3: 2 | W3: 3 | X3: 4 | Y3: 5 | Z3: 6 | AA3: 7 | AB3: CN | AC3: 2 | AD3: 3 | AE3: 4 | AF3: 5 | AG3: 6 | AH3: 7 | AI3: CN | AJ3: 2 | AK3: 3 | AL3: 4 | AM3: 5 | AN3: 6 | AO3: 7 | AP3: CN | AQ3: 2 | AR3: 3 | AS3: 4 | AT3: 5 | AU3: 6 | AV3: 7 | AW3: CN | AX3: 2 | AY3: 3 | AZ3: 4 | BA3: 5 | BB3: 6 | BC3: 7 | BD3: CN | BE3: 2 | BF3: 3 | BG3: 4 | BH3: 5 | BI3: 6 | BJ3: 7 | BK3: CN | BL3: 2 | BM3: 3 | BN3: 4 | BO3: 5 | BP3: 6 | BQ3: 7 | BR3: CN | BS3: 2 | BT3: 3 | BU3: 4 | BV3: 5 | BW3: 6 | BX3: 7 | BY3: CN | BZ3: 2 | CA3: 3 | CB3: 4 | CC3: 5 | CD3: 6 | CE3: 7 | CF3: CN | CG3: 2 | CH3: 3 | CI3: 4 | CJ3: 5 | CK3: 6 | CL3: 7 | CM3: CN | CN3: 2 | CO3: 3 | CP3: 4 | CQ3: 5 | CR3: 6 | CS3: 7 | CT3: CN | CU3: 2 | CV3: 3 | CW3: 4 | CX3: 5 | CY3: 6 | CZ3: 7 | DA3: CN | DB3: 2 | DC3: 3 | DD3: 4 | DE3: 5 | DF3: 6 | DG3: 7 | DH3: CN | DI3: 2 | DJ3: 3 | DK3: 4 | DL3: 5 | DM3: 6 | DN3: 7 | DO3: CN | DP3: 2 | DQ3: 3 | DR3: 4 | DS3: 5 | DT3: 6 | DU3: 7 | DV3: CN | DW3: 2 | DX3: 3 | DY3: 4 | DZ3: 5 | EA3: 6 | EB3: 7 | EC3: CN | ED3: 2 | EE3: 3 | EF3: 4 | EG3: 5 | EH3: 6 | EI3: 7 | EJ3: CN | EK3: 2 | EL3: 3 | EM3: 4 | EN3: 5 | EO3: 6 | EP3: 7 | EQ3: CN | ER3: 2 | ES3: 3 | ET3: 4 | EU3: 5 | EV3: 6 | EW3: 7 | EX3: CN | EY3: 2 | EZ3: 3 | FA3: 4 | FB3: 5 | FC3: 6 | FD3: 7 | FE3: CN | FF3: 2 | FG3: 3 | FH3: 4 | FI3: 5 | FJ3: 6 | FK3: 7 | FL3: CN | FM3: 2 | FN3: 3 | FO3: 4 | FP3: 5 | FQ3: 6 | FR3: 7 | FS3: CN | FT3: 2 | FU3: 3 | FV3: 4 | FW3: 5 | FX3: 6 | FY3: 7 | FZ3: CN | GA3: 2 | GB3: 3 | GC3: 4 | GD3: 5 | GE3: 6 | GF3: 7 | GG3: CN | GH3: 2 | GI3: 3 | GJ3: 4 | GK3: 5 | GL3: 6 | GM3: 7 | GN3: CN | GO3: 2 | GP3: 3 | GQ3: 4 | GR3: 5 | GS3: 6 | GT3: 7 | GU3: CN | GV3: 2 | GW3: 3 | GX3: 4 | GY3: 5 | GZ3: 6 | HA3: 7 | HB3: CN | HC3: 2 | HD3: 3 | HE3: 4 | HF3: 5 | HG3: 6 | HH3: 7 | HI3: CN | HJ3: 2 | HK3: 3 | HL3: 4 | HM3: 5 | HN3: 6 | HO3: 7 | HP3: CN | HQ3: 2 | HR3: 3 | HS3: 4 | HT3: 5 | HU3: 6 | HV3: 7 | HW3: CN | HX3: 2 | HY3: 3 | HZ3: 4 | IA3: 5 | IB3: 6 | IC3: 7 | ID3: CN | IE3: 2 | IF3: 3 | IG3: 4 | IH3: 5 | II3: 6 | IJ3: 7 | IK3: CN | IL3: 2 | IM3: 3 | IN3: 4 | IO3: 5 | IP3: 6 | IQ3: 7 | IR3: CN | IS3: 2 | IT3: 3 | IU3: 4 | IV3: 5 | IW3: 6 | IX3: 7 | IY3: CN | IZ3: 2 | JA3: 3 | JB3: 4 | JC3: 5 | JD3: 6 | JE3: 7 | JF3: CN | JG3: 2 | JH3: 3 | JI3: 4 | JJ3: 5 | JK3: 6 | JL3: 7 | JM3: CN | JN3: 2 | JO3: 3 | JP3: 4 | JQ3: 5 | JR3: 6 | JS3: 7 | JT3: CN | JU3: 2 | JV3: 3 | JW3: 4 | JX3: 5 | JY3: 6 | JZ3: 7 | KA3: CN | KB3: 2 | KC3: 3 | KD3: 4 | KE3: 5 | KF3: 6 | KG3: 7 | KH3: CN | KI3: 2 | KJ3: 3 | KK3: 4 | KL3: 5 | KM3: 6 | KN3: 7 | KO3: CN | KP3: 2 | KQ3: 3 | KR3: 4 | KS3: 5 | KT3: 6 | KU3: 7 | KV3: CN | KW3: 2 | KX3: 3 | KY3: 4 | KZ3: 5 | LA3: 6 | LB3: 7 | LC3: CN | LD3: 2 | LE3: 3 | LF3: 4 | LG3: 5 | LH3: 6 | LI3: 7 | LJ3: CN | LK3: 2 | LL3: 3 | LM3: 4 | LN3: 5 | LO3: 6 | LP3: 7 | LQ3: CN | LR3: 2 | LS3: 3 | LT3: 4 | LU3: 5 | LV3: 6 | LW3: 7 | LX3: CN | LY3: 2 | LZ3: 3 | MA3: 4 | MB3: 5 | MC3: 6 | MD3: 7 | ME3: CN | MF3: 2 | MG3: 3 | MH3: 4 | MI3: 5 | MJ3: 6 | MK3: 7 | ML3: CN | MM3: 2 | MN3: 3 | MO3: 4 | MP3: 5 | MQ3: 6 | MR3: 7 | MS3: CN | MT3: 2 | MU3: 3 | MV3: 4 | MW3: 5 | MX3: 6 | MY3: 7 | MZ3: CN | NA3: 2 | NB3: 3 | NC3: 4 | ND3: 5 | NE3: 6 | NF3: 7 | NG3: CN | NH3: 2 | NI3: 3 | NJ3: 4 | NK3: 5 | NL3: 6 | NM3: 7 | NN3: CN
A4: REV(M) | C4: =ROUND(REV!B4/1000000,0) -> 819 | D4: =ROUND(REV!C4/1000000,0) -> 621 | E4: =ROUND(REV!D4/1000000,0) -> 2038 | F4: =ROUND(REV!E4/1000000,0) -> 1379 | G4: =ROUND(REV!F4/1000000,0) -> 908 | H4: =ROUND(REV!G4/1000000,0) -> 1407 | I4: =ROUND(REV!H4/1000000,0) -> 843 | J4: =ROUND(REV!I4/1000000,0) -> 718 | ... NC4: =ROUND(REV!NB4/1000000,0) -> 475
A5: Plan vận hành | B5: 1 | H5: TNTB | W5: Promotion Tết (4.7B, 4.2K PU) | AM5: TNTB (1.5B, 1.5K PU) | AU5: Valentine (2B, 4K PU) | BG5: Thần Thạch Bí Ẩn (2.2B, 4K PU) | CP5: Nạp Hoàn Trả | DQ5: Giải đấu Vô Song Hào Kiệt | EK5: Quà Vào Hạ (1.7B, 2.8K PU) | EY5: Nạp Hoàn Trả | FP5: Quà Mùa Hè (1.8B, 3K PU) | GJ5: 长歌诗韵-Trường Ca Thơ Vận (1.9B, 4.9K PU) | HG5: Nạp Hoàn Trả | HZ5: Thước Kiều Tầm Duyên (1.9B, 1.1K PU) | IN5: Ghi Danh và Thông Báo Giải Đấu Nhất Kiếm Kinh Thiên | JK5: Quà Tặng Thân Tình (1.1B, 2.7K PU) | KE5: Dự Báo | KK5: Quà Tuyệt Sắc (1.6B, 2.6K PU) | KY5: Vòng Chung Kết (Liên Máy Chủ) | LK5: Tổng Kết Vòng CK | LV5: Black Friday | MJ5: Rương Thiên Giáng Hồng Phúc (1.7B, 3.6K PU) | MV5: Quà Giáng Sinh (1.6B, 2.5K PU)
B6: 2 | E6: Nạp Hoàn Trả | R6: Quà Khai Xuân (2.2B, 3.6K PU) | AJ6: Nạp Hoàn Trả | BA6: Quà Du Xuân (2.1B, 3.2K PU) | CG6: Promotion Sinh Nhật (3.8B, 3.2K PU) | CV6: TNTB (1.2B, 1.2K PU) | DB6: Rương Thiên Giáng Hồng Phúc (2B, 4.3K PU) | DT6: Báo Danh | EU6: Promotion Kho Báu Mùa Hè (1.6B, 1.9K PU) | FJ6: Thần Thạch Bí Ẩn (1.6B, 2.9K PU) | GJ6: 奇珍阁特惠- Ưu đãi KTC | HJ6: TNTB (1.2B, 1.2K PU) | HN6: Thần Thạch Bí Ẩn (2.3B, 3.7K PU) | HZ6: Chân Tình Bảo Rương | IN6: Nhất Kiếm Chiêu Anh (1.5B, 4.2K PU) | JB6: Dự Đoán | JK6: Tiệc Đoàn Viên | KJ6: Báo Danh | KT6: Tổng Kết Vòng Loại | LB6: TNTB (1B, 1.1K PU) | MA6: Nạp Hoàn Trả
B7: 3 | C7: Ưu Đãi 01-01 (624M, 2.5K PU) | K7: Khởi Niên Tầm Duyên (2.8B, 2.7K PU) | Z7: Chuỗi event Tết Nguyên Đán | BO7: TNTB (1.3B, 1.3K PU) | CB7: Quà Sinh Nhật (2.1B, 3.5K PU) | CR7: Giỗ Tổ Hùng Vương: Ghép (1.8 B, 5.1K PU), Quà (2B, 3.1K PU) | DX7: Sơ Tuyển | EE7: Đấu Loại | EO7: Số Tay Tuổi Thơ | FB7: Đua Thuyền Rồng | FT7: Thiên Y Các | GJ7: 再闯江湖 - Tái xuất giang hồ | HZ7: Đồng Tâm Tình Duyên | IO7: Vòng Sơ Tuyển | IV7: Vòng Loại | JB7: Top 32 | JC7: Top 8 | JD7: Tứ Kết | JE7: Bán Kết | JK7: Hộp Quà Trung Thu (1.8B, 3.1K PU) | KJ7: Vòng Loại (Máy Chủ) | KW7: Nạp Hoàn Trả | LM7: Bức Họa Sư Đồ | MF7: TNTB (1B, 1.12K PU)
B8: 4 | Y8: Promotion Webshop | BL8: Nạp Hoàn Trả | CN8: Tầm Duyên Hoa Vũ (2.5B, 2.3K PU) | DI8: Quà Mừng Lễ | EE8: Dự Đoán | EO8: Công Viên Giải Trí (1.6B, 3.6k PU) | FB8: Quà Đoan Ngọ (1.7B, 3.1K PU) | FW8: Nhật Hạ Tầm Duyên (2.3B, 2.1K PU) | GJ8: 首充双倍-X2 nạp đầu | HZ8: Thiên Y Các | IL8: Nạp Hoàn Trả | JB8: Top 16 | JE8: Chung Kết | JK8: Thỏ Ngọc Ủ Rượu | KE8: Khuynh Quốc Khuynh Thành (1B, 2.8K PU) | KR8: Rương Phúc Tinh Cao Chiếu (1.6B, 3.5K PU) | LM8: Tri Ân Sư Đồ (1.1B, 3K PU) | MH8: Vòng Tuyển Chọn (0.66B, 2.9K PU) | MP8: Vòng Tranh Đoạt | MW8: Vòng Chung Kết
B9: 5 | AS9: Tết Nguyên Tiêu (1.5B, 3.4K PU) | BU9: Đào Hoa (ghép) (2.1B, 6K PU) + làm bánh đua top (274M + 3K PU) | DM9: Event Lao Động (Ghép 1.3B, 3.4K PU), (Thần Thạch 1.6B, 3.1K PU) | EG9: Top 8 | EO9: Thổi Bong Bóng | FB9: Búp Bê Hoài Cổ | GJ9: 资料片礼物-Quà BU | HC9: Rương Phú Quý Cát Tường (2.2B, 4.3K PU) | IG9: Giang Sơn Như Họa (1.4B, 3.4K PU) | IR9: TNTB | IV9: Rương Tường Vân Đại Cát (2.3B, 4.3K PU) | JG9: Quà Trung Thu (1.7B, 2.7K PU) | JU9: TNTB | KE9: Hoa Hải Mịch Duyên (1.6B, 898 PU) | LM9: Quà Sư Đồ (1.5B, 2.7K PU) | MC9: Tầm Duyên Ngày Đông (1.8B, 1K PU) | MP9: D1 | MR9: D2 | MS9: D3 | MU9: D4 | MW9: T32 | MY9: T32 | MZ9: T16 | NB9: T8 | NI9: T4 | NK9: T2 - T1
B10: 6 | AS10: Giải Đấu Siêu Sao Đại Chiến | BU10: Boss Đào Hoa | DT10: Nạp Hoàn Trả | EG10: Top 4 | EH10: Bán Kết | EI10: Chung Kết | EO10: Đại Chiến Bãi Biển | FB10: Kẻ Trộm Thanh Xuân | GD10: TNTB (1.2B, 1.2K PU) | GJ10: 烟花庆典-Pháo hoa mừng lễ | GX10: 夏日钓鱼_Câu Cá Ngày Hè (1.3B, 2.5K PU) | IG10: Ưu Đãi KTC | JB10: Thần Thạch Bí Ẩn (1.8B, 3.3K PU) | JP10: Nạp Hoàn Trả | LM10: Đại Chiến Bãi Biển | NB10: Dự Đoán
B11: 7 | AS11: Tuyển Chọn (Đua Top 50 TP LSV) | BU11: Giảm Giá KTC | DD11: Phó bản Thiên Quỳnh Cung (mới) (tàng bảo đồ) | DW11: TNTB (1.3B, 1.3K PU) | EE11: Tầm Duyên Mùa Hè (2.5B, 2.3K PU) | FB11: Đoan Ngọ Gói Bánh (1.4B, 2.8K PU) | GB11: Nạp Hoàn Trả | GR11: Quà Trường Ca (1.8B, 2.7K PU) | IG11: Giảm giá nhận lại | JC11: Bonus thưởng nạp 100K | JY11: Ưu Đãi 10-10 | LF11: Thần Thạch Bí Ẩn (1.6B, 2.9K PU) | LR11: Quà Nhất Phẩm (1.5B, K PU) | MO11: Ném Tuyết
B12: 8 | BA12: Đấu Loại | CE12: Bang Hội Khiêu Chiến -> đánh Bánh Kem | DD12: Ưu hóa cải thiện gameplay Loạn đấu môn phái | FE12: TNTB (1.2B, 1.2K PU) | HT12: Quà Tình Duyên (1.8B, 2.8K PU) | IG12: Năng Động Mừng Lễ | KD12: Gửi gói đầu | KK12: Gửi gói 2 | KQ12: submit iOS | KT12: submit storekit android | KY12: 西夏一品_Nhất Phẩm Tây Hạ (1.7B, 4.7K PU) | MO12: Băng Tuyết Đại Đạo
B13: 9 | BB13: Dự Đoán | BU13: Tái Xuất Giang Hồ (kết hợp ưu hóa mời bạn) | DD13: Ưu hóa lĩnh ngộ chung cho hê thống thức tỉnh đồng hành | FH13: Kỹ Năng Thú B5 | FV13: Thần Binh 10 Sao | IG13: Ưu đãi cuối tuần | KY13: 奇珍阁特惠- Ưu đãi KTC | MO13: Trang Trí Cây Thông (1B, 1.9K PU)
B14: 10 | BC14: Chung Kết | BU14: Reset X2 NB, Quà BU | DD14: Ưu hóa Rương Thần Binh nhận từ Lò Thần có thể giao dịch/bày bán | HL14: PB quân doanh mới: Hải Lăng Vương Mộ | KY14: 福运周卡_Phúc Vận Thẻ Tuần | MO14: Hộp Quà Giáng Sinh (1.3B, 2.6K PU)
B15: 11 | BU15: Pháo Hoa Mừng Lễ | DD15: Mở rộng ưu đãi chỉ số cho người đến sau mở rộng từ KT9 trở đi | KY15: 再闯江湖 - Tái xuất giang hồ
A16: Technical | B16: 12 | KY16: 首充双倍-X2 nạp đầu
B17: 13 | KY17: 资料片礼物-Quà BU
B18: 14 | KY18: 烟花庆典-Pháo hoa mừng lễ
A19: Data | B19: 15
B20: 16
B21: 17
B22: 18
A23: MKT | B23: 19 | CJ23: Mở S300 - Trường Sinh Kiếm (Sinh Nhật 2T)
B24: 20
B26: 21
A27: Other | B27: 22 | BU27: Đào Hoa | CB27: Level Up softlaunch | GJ27: Trường Ca | KY27: Nhất Phẩm Đường
B28: 23 | BU28: Thần Binh | GJ28: Trận Pháp Đồng Hành | KY28: Bộ Trấn Nhạc
B29: 23 | BU29: Loạn Chiến Môn Phái | GJ29: Thủ Vệ Tương Dương | KY29: Hiệp Khách Đảo
B30: 24 | GJ30: Lãnh Thổ Chiến LSV
B31: 24

Sheet 2026
A1: =TODAY() -> 46121 | C1: T1/2025 | AH1: T2/2025 | BJ1: T3/2025 | CO1: T4/2025 | DS1: T5/2025 | EX1: T6/2025 | GB1: T7/2025 | HG1: T8/2025 | IL1: T9/2025 | JP1: T10/2025 | KU1: T11/2025 | LY1: T12/2025
A2: =SUM(C4:NC4) -> 69296 | C2: 46023 | D2: 46024 | E2: 46025 | F2: 46026 | G2: 46027 | H2: 46028 | I2: 46029 | J2: 46030 | K2: 46031 | L2: 46032 | M2: 46033 | N2: 46034 | O2: 46035 | P2: 46036 | Q2: 46037 | R2: 46038 | S2: 46039 | T2: 46040 | U2: 46041 | V2: 46042 | W2: 46043 | X2: 46044 | Y2: 46045 | Z2: 46046 | AA2: 46047 | AB2: 46048 | AC2: 46049 | AD2: 46050 | AE2: 46051 | AF2: 46052 | AG2: 46053 | AH2: 46054 | AI2: 46055 | AJ2: 46056 | AK2: 46057 | AL2: 46058 | AM2: 46059 | AN2: 46060 | AO2: 46061 | AP2: 46062 | AQ2: 46063 | AR2: 46064 | AS2: 46065 | AT2: 46066 | AU2: 46067 | AV2: 46068 | AW2: 46069 | AX2: 46070 | AY2: 46071 | AZ2: 46072 | BA2: 46073 | BB2: 46074 | BC2: 46075 | BD2: 46076 | BE2: 46077 | BF2: 46078 | BG2: 46079 | BH2: 46080 | BI2: 46081 | BJ2: 46082 | BK2: 46083 | BL2: 46084 | BM2: 46085 | BN2: 46086 | BO2: 46087 | BP2: 46088 | BQ2: 46089 | BR2: 46090 | BS2: 46091 | BT2: 46092 | BU2: 46093 | BV2: 46094 | BW2: 46095 | BX2: 46096 | BY2: 46097 | BZ2: 46098 | CA2: 46099 | CB2: 46100 | CC2: 46101 | CD2: 46102 | CE2: 46103 | CF2: 46104 | CG2: 46105 | CH2: 46106 | CI2: 46107 | CJ2: 46108 | CK2: 46109 | CL2: 46110 | CM2: 46111 | CN2: 46112 | CO2: 46113 | CP2: 46114 | CQ2: 46115 | CR2: 46116 | CS2: 46117 | CT2: 46118 | CU2: 46119 | CV2: 46120 | CW2: 46121 | CX2: 46122 | CY2: 46123 | CZ2: 46124 | DA2: 46125 | DB2: 46126 | DC2: 46127 | DD2: 46128 | DE2: 46129 | DF2: 46130 | DG2: 46131 | DH2: 46132 | DI2: 46133 | DJ2: 46134 | DK2: 46135 | DL2: 46136 | DM2: 46137 | DN2: 46138 | DO2: 46139 | DP2: 46140 | DQ2: 46141 | DR2: 46142 | DS2: 46143 | DT2: 46144 | DU2: 46145 | DV2: 46146 | DW2: 46147 | DX2: 46148 | DY2: 46149 | DZ2: 46150 | EA2: 46151 | EB2: 46152 | EC2: 46153 | ED2: 46154 | EE2: 46155 | EF2: 46156 | EG2: 46157 | EH2: 46158 | EI2: 46159 | EJ2: 46160 | EK2: 46161 | EL2: 46162 | EM2: 46163 | EN2: 46164 | EO2: 46165 | EP2: 46166 | EQ2: 46167 | ER2: 46168 | ES2: 46169 | ET2: 46170 | EU2: 46171 | EV2: 46172 | EW2: 46173 | EX2: 46174 | EY2: 46175 | EZ2: 46176 | FA2: 46177 | FB2: 46178 | FC2: 46179 | FD2: 46180 | FE2: 46181 | FF2: 46182 | FG2: 46183 | FH2: 46184 | FI2: 46185 | FJ2: 46186 | FK2: 46187 | FL2: 46188 | FM2: 46189 | FN2: 46190 | FO2: 46191 | FP2: 46192 | FQ2: 46193 | FR2: 46194 | FS2: 46195 | FT2: 46196 | FU2: 46197 | FV2: 46198 | FW2: 46199 | FX2: 46200 | FY2: 46201 | FZ2: 46202 | GA2: 46203 | GB2: 46204 | GC2: 46205 | GD2: 46206 | GE2: 46207 | GF2: 46208 | GG2: 46209 | GH2: 46210 | GI2: 46211 | GJ2: 46212 | GK2: 46213 | GL2: 46214 | GM2: 46215 | GN2: 46216 | GO2: 46217 | GP2: 46218 | GQ2: 46219 | GR2: 46220 | GS2: 46221 | GT2: 46222 | GU2: 46223 | GV2: 46224 | GW2: 46225 | GX2: 46226 | GY2: 46227 | GZ2: 46228 | HA2: 46229 | HB2: 46230 | HC2: 46231 | HD2: 46232 | HE2: 46233 | HF2: 46234 | HG2: 46235 | HH2: 46236 | HI2: 46237 | HJ2: 46238 | HK2: 46239 | HL2: 46240 | HM2: 46241 | HN2: 46242 | HO2: 46243 | HP2: 46244 | HQ2: 46245 | HR2: 46246 | HS2: 46247 | HT2: 46248 | HU2: 46249 | HV2: 46250 | HW2: 46251 | HX2: 46252 | HY2: 46253 | HZ2: 46254 | IA2: 46255 | IB2: 46256 | IC2: 46257 | ID2: 46258 | IE2: 46259 | IF2: 46260 | IG2: 46261 | IH2: 46262 | II2: 46263 | IJ2: 46264 | IK2: 46265 | IL2: 46266 | IM2: 46267 | IN2: 46268 | IO2: 46269 | IP2: 46270 | IQ2: 46271 | IR2: 46272 | IS2: 46273 | IT2: 46274 | IU2: 46275 | IV2: 46276 | IW2: 46277 | IX2: 46278 | IY2: 46279 | IZ2: 46280 | JA2: 46281 | JB2: 46282 | JC2: 46283 | JD2: 46284 | JE2: 46285 | JF2: 46286 | JG2: 46287 | JH2: 46288 | JI2: 46289 | JJ2: 46290 | JK2: 46291 | JL2: 46292 | JM2: 46293 | JN2: 46294 | JO2: 46295 | JP2: 46296 | JQ2: 46297 | JR2: 46298 | JS2: 46299 | JT2: 46300 | JU2: 46301 | JV2: 46302 | JW2: 46303 | JX2: 46304 | JY2: 46305 | JZ2: 46306 | KA2: 46307 | KB2: 46308 | KC2: 46309 | KD2: 46310 | KE2: 46311 | KF2: 46312 | KG2: 46313 | KH2: 46314 | KI2: 46315 | KJ2: 46316 | KK2: 46317 | KL2: 46318 | KM2: 46319 | KN2: 46320 | KO2: 46321 | KP2: 46322 | KQ2: 46323 | KR2: 46324 | KS2: 46325 | KT2: 46326 | KU2: 46327 | KV2: 46328 | KW2: 46329 | KX2: 46330 | KY2: 46331 | KZ2: 46332 | LA2: 46333 | LB2: 46334 | LC2: 46335 | LD2: 46336 | LE2: 46337 | LF2: 46338 | LG2: 46339 | LH2: 46340 | LI2: 46341 | LJ2: 46342 | LK2: 46343 | LL2: 46344 | LM2: 46345 | LN2: 46346 | LO2: 46347 | LP2: 46348 | LQ2: 46349 | LR2: 46350 | LS2: 46351 | LT2: 46352 | LU2: 46353 | LV2: 46354 | LW2: 46355 | LX2: 46356 | LY2: 46357 | LZ2: 46358 | MA2: 46359 | MB2: 46360 | MC2: 46361 | MD2: 46362 | ME2: 46363 | MF2: 46364 | MG2: 46365 | MH2: 46366 | MI2: 46367 | MJ2: 46368 | MK2: 46369 | ML2: 46370 | MM2: 46371 | MN2: 46372 | MO2: 46373 | MP2: 46374 | MQ2: 46375 | MR2: 46376 | MS2: 46377 | MT2: 46378 | MU2: 46379 | MV2: 46380 | MW2: 46381 | MX2: 46382 | MY2: 46383 | MZ2: 46384 | NA2: 46385 | NB2: 46386 | NC2: 46387
A3: =A2/277547 -> 0.24967303 | C3: 5 | D3: 6 | E3: 7 | F3: CN | G3: 2 | H3: 3 | I3: 4 | J3: 5 | K3: 6 | L3: 7 | M3: CN | N3: 2 | O3: 3 | P3: 4 | Q3: 5 | R3: 6 | S3: 7 | T3: CN | U3: 2 | V3: 3 | W3: 4 | X3: 5 | Y3: 6 | Z3: 7 | AA3: CN | AB3: 2 | AC3: 3 | AD3: 4 | AE3: 5 | AF3: 6 | AG3: 7 | AH3: CN | AI3: 2 | AJ3: 3 | AK3: 4 | AL3: 5 | AM3: 6 | AN3: 7 | AO3: CN | AP3: 2 | AQ3: 3 | AR3: 4 | AS3: 5 | AT3: 6 | AU3: 7 | AV3: CN | AW3: 2 | AX3: 3 | AY3: 4 | AZ3: 5 | BA3: 6 | BB3: 7 | BC3: CN | BD3: 2 | BE3: 3 | BF3: 4 | BG3: 5 | BH3: 6 | BI3: 7 | BJ3: CN | BK3: 2 | BL3: 3 | BM3: 4 | BN3: 5 | BO3: 6 | BP3: 7 | BQ3: CN | BR3: 2 | BS3: 3 | BT3: 4 | BU3: 5 | BV3: 6 | BW3: 7 | BX3: CN | BY3: 2 | BZ3: 3 | CA3: 4 | CB3: 5 | CC3: 6 | CD3: 7 | CE3: CN | CF3: 2 | CG3: 3 | CH3: 4 | CI3: 5 | CJ3: 6 | CK3: 7 | CL3: CN | CM3: 2 | CN3: 3 | CO3: 4 | CP3: 5 | CQ3: 6 | CR3: 7 | CS3: CN | CT3: 2 | CU3: 3 | CV3: 4 | CW3: 5 | CX3: 6 | CY3: 7 | CZ3: CN | DA3: 2 | DB3: 3 | DC3: 4 | DD3: 5 | DE3: 6 | DF3: 7 | DG3: CN | DH3: 2 | DI3: 3 | DJ3: 4 | DK3: 5 | DL3: 6 | DM3: 7 | DN3: CN | DO3: 2 | DP3: 3 | DQ3: 4 | DR3: 5 | DS3: 6 | DT3: 7 | DU3: CN | DV3: 2 | DW3: 3 | DX3: 4 | DY3: 5 | DZ3: 6 | EA3: 7 | EB3: CN | EC3: 2 | ED3: 3 | EE3: 4 | EF3: 5 | EG3: 6 | EH3: 7 | EI3: CN | EJ3: 2 | EK3: 3 | EL3: 4 | EM3: 5 | EN3: 6 | EO3: 7 | EP3: CN | EQ3: 2 | ER3: 3 | ES3: 4 | ET3: 5 | EU3: 6 | EV3: 7 | EW3: CN | EX3: 2 | EY3: 3 | EZ3: 4 | FA3: 5 | FB3: 6 | FC3: 7 | FD3: CN | FE3: 2 | FF3: 3 | FG3: 4 | FH3: 5 | FI3: 6 | FJ3: 7 | FK3: CN | FL3: 2 | FM3: 3 | FN3: 4 | FO3: 5 | FP3: 6 | FQ3: 7 | FR3: CN | FS3: 2 | FT3: 3 | FU3: 4 | FV3: 5 | FW3: 6 | FX3: 7 | FY3: CN | FZ3: 2 | GA3: 3 | GB3: 4 | GC3: 5 | GD3: 6 | GE3: 7 | GF3: CN | GG3: 2 | GH3: 3 | GI3: 4 | GJ3: 5 | GK3: 6 | GL3: 7 | GM3: CN | GN3: 2 | GO3: 3 | GP3: 4 | GQ3: 5 | GR3: 6 | GS3: 7 | GT3: CN | GU3: 2 | GV3: 3 | GW3: 4 | GX3: 5 | GY3: 6 | GZ3: 7 | HA3: CN | HB3: 2 | HC3: 3 | HD3: 4 | HE3: 5 | HF3: 6 | HG3: 7 | HH3: CN | HI3: 2 | HJ3: 3 | HK3: 4 | HL3: 5 | HM3: 6 | HN3: 7 | HO3: CN | HP3: 2 | HQ3: 3 | HR3: 4 | HS3: 5 | HT3: 6 | HU3: 7 | HV3: CN | HW3: 2 | HX3: 3 | HY3: 4 | HZ3: 5 | IA3: 6 | IB3: 7 | IC3: CN | ID3: 2 | IE3: 3 | IF3: 4 | IG3: 5 | IH3: 6 | II3: 7 | IJ3: CN | IK3: 2 | IL3: 3 | IM3: 4 | IN3: 5 | IO3: 6 | IP3: 7 | IQ3: CN | IR3: 2 | IS3: 3 | IT3: 4 | IU3: 5 | IV3: 6 | IW3: 7 | IX3: CN | IY3: 2 | IZ3: 3 | JA3: 4 | JB3: 5 | JC3: 6 | JD3: 7 | JE3: CN | JF3: 2 | JG3: 3 | JH3: 4 | JI3: 5 | JJ3: 6 | JK3: 7 | JL3: CN | JM3: 2 | JN3: 3 | JO3: 4 | JP3: 5 | JQ3: 6 | JR3: 7 | JS3: CN | JT3: 2 | JU3: 3 | JV3: 4 | JW3: 5 | JX3: 6 | JY3: 7 | JZ3: CN | KA3: 2 | KB3: 3 | KC3: 4 | KD3: 5 | KE3: 6 | KF3: 7 | KG3: CN | KH3: 2 | KI3: 3 | KJ3: 4 | KK3: 5 | KL3: 6 | KM3: 7 | KN3: CN | KO3: 2 | KP3: 3 | KQ3: 4 | KR3: 5 | KS3: 6 | KT3: 7 | KU3: CN | KV3: 2 | KW3: 3 | KX3: 4 | KY3: 5 | KZ3: 6 | LA3: 7 | LB3: CN | LC3: 2 | LD3: 3 | LE3: 4 | LF3: 5 | LG3: 6 | LH3: 7 | LI3: CN | LJ3: 2 | LK3: 3 | LL3: 4 | LM3: 5 | LN3: 6 | LO3: 7 | LP3: CN | LQ3: 2 | LR3: 3 | LS3: 4 | LT3: 5 | LU3: 6 | LV3: 7 | LW3: CN | LX3: 2 | LY3: 3 | LZ3: 4 | MA3: 5 | MB3: 6 | MC3: 7 | MD3: CN | ME3: 2 | MF3: 3 | MG3: 4 | MH3: 5 | MI3: 6 | MJ3: 7 | MK3: CN | ML3: 2 | MM3: 3 | MN3: 4 | MO3: 5 | MP3: 6 | MQ3: 7 | MR3: CN | MS3: 2 | MT3: 3 | MU3: 4 | MV3: 5 | MW3: 6 | MX3: 7 | MY3: CN | MZ3: 2 | NA3: 3 | NB3: 4 | NC3: 5
A4: REV(M) | C4: =ROUND(REV!B6/1000000,0) -> 648 | D4: =ROUND(REV!C6/1000000,0) -> 429 | E4: =ROUND(REV!D6/1000000,0) -> 1571 | F4: =ROUND(REV!E6/1000000,0) -> 955 | G4: =ROUND(REV!F6/1000000,0) -> 899 | H4: =ROUND(REV!G6/1000000,0) -> 962 | I4: =ROUND(REV!H6/1000000,0) -> 782 | J4: =ROUND(REV!I6/1000000,0) -> 544 | ... NC4: =ROUND(REV!NB6/1000000,0) -> 0
A5: Plan vận hành | B5: 1 | E5: Nạp Hoàn Trả | AH5: Nạp Hoàn Trả | BM5: Nạp Hoàn Trả | CR5: Nạp Hoàn Trả | DV5: Nạp Hoàn Trả
B6: 2 | H6: TNTB (1B, 1.17K PU) | AO6: TNTB | BS6: TNTB | CU6: TNTB | EB6: TNTB
B7: 3 | Z7: Quà Khai Xuân (1.6B, 2.5K PU) | BG7: Quà Du Xuân (1.4B, 2.2K PU) | CH7: Quà Sinh Nhật (B, K PU) | DL7: Quà Mừng Lễ (B, K PU) | EN7: Quà (B, K PU)
B8: 4 | AE8: Rương Phúc Mãn Nhân Gian (1.1B, 3K PU) | BS8: Rương Phúc Lộc Tề Thiên (1.7B, 2.6K PU)
B9: 5 | BO9: Phượng Các Tầm Duyên (1.6B, 1.5K PU) | CX9: Tầm Duyên (B, K PU) | ES9: Tầm Duyên (B, K PU)
B10: 6 | K10: Thần Thạch Bí Ẩn (1.8B, 3.1K PU) | BC10: Thần Thạch Bí Ẩn (1.6B, 2.8K PU) | CO10: Thần Thạch Bí Ẩn (B, K PU) | EE10: Thần Thạch Bí Ẩn (B, K PU)
B11: 7 | C11: Chuỗi Event Chào Mừng Năm Mới | Q11: Chuỗi Event Vui Xuân Trẩy Hội | AL11: Promotion Tết - Mã Đáo Vinh Hoa (3.3B, 2K PU) | CA11: Chuỗi Event PBM: Nghịch Thế Võ Hồn (B, K PU)
B12: 8 | C12: Ưu Đãi 01-01 (0.5B, 2.3K PU) | Q12: Vui Xuân Trẩy Hội (0.6B, 2.1K PU) | AR12: Chuỗi event Tết | BH12: Chuỗi Event Tết Nguyên Tiêu | CA12: Nghịch Thế Võ Hồn (1.1B, 2.6K PU) | DD12: GIỗ Tổ | EF12: Vô Song Hào Kiệt | FI12: Sưu Tầm Quốc Kỳ | GP12: Săn Bóng WC
B13: 9 | C13: Năm Mới Năng Động | U13: Dạ Lan Quan | AM13: Tài Vận Hanh Thông | BH13: Đố Đèn Hoa Đăng | CA13: 奇珍阁特惠- Ưu đãi KTC | DD13: Mâm Cỗ Tiến Vua | EF13: Báo Danh | GI13: Trổ Tài Dự Đoán
B14: 10 | C14: Giảm Giá Nhận Lại | V14: Khởi Niên Tầm Duyên (1.6B, 1.4K PU) | AW14: Tiệc Tất Niên | BH14: Món Ngon Nguyên Tiêu (1.2B, 3K PU) | CA14: 再闯江湖 - Tái xuất giang hồ | DD14: Dâng Hương Bái Tổ | EK14: Sơ Tuyển | ER14: Đấu Loại
B15: 11 | C15: Năm Mới x2 | AR15: Cùng Vui Đón Tết | BH15: Tiệc Nguyên Tiêu | CA15: 首充双倍-X2 nạp đầu | DI15: Hộp Quà Mừng Lễ | ER15: Dự Đoán
B16: 12 | AW16: Lì Xì Phúc Vận | CA16: 资料片礼物-Quà BU | DI16: Bảo Vệ Hồn Tổ Tiên | DO16: Lao Động | EJ16: 奇珍阁特惠- Ưu đãi KTC | ET16: Top 8
B17: 13 | H17: T4 | J17: T2 - T1 | AW17: Đếm Ngược Tân Xuân | CA17: 烟花庆典-Pháo hoa mừng lễ | DO17: Làm Vườn | ET17: Top 4 | EX17: Bán Kết | EZ17: Chung Kết
B18: 14 | AP18: Ưu Đãi Tân Niên | CF18: Chuỗi Event Sinh Nhật 3 Tuổi: Minh Đăng Yến Hội | DT18: Rương
B19: 15 | AM19: Ưu Đãi Nhận Lại | CF19: Promotion Bánh Kem Sinh Nhật | DO19: Điểm Danh
B20: 16 | AM20: Cuối Tuần x2 | CF20: Promotion Mừng Tiệc Sinh Thần | DO20: X2 Cuối tuần
B21: 17 | AR21: Event Valentine | CF21: Promotion Bằng Hữu Nghĩa Tình | DO21: Giảm giá nhận lại
B22: 18 | AR22: Ưu Đãi Ngoại Quan Tình Nhân | CJ22: Event Sinh Nhật
B23: 19 | AR23: Quà Tình Nhân
B24: 20 | AQ24: Gửi gói đầu | AW24: Lộc Xuân Rộn Ràng | BH24: Gửi gói 2 | BN24: submit iOS | BT24: submit storekit android | CA24: BU
B25: 21
A26: Technical | B26: 22
B27: 23
B28: 24
A29: Data | B29: 25
B30: 26
B31: 27
B32: 28
A33: MKT | B33: 29
B34: 30
B35: 31
B36: 32
A37: Other | B37: 33
B38: 34
B39: 35
B40: 36
...

Sheet REV
